Failure # 1 (occurred at 2022-11-17_22-40-56)
[36mray::ImplicitFunc.train()[39m (pid=10993, ip=172.22.196.137, repr=tuning)
  File "/home/joe/.conda/envs/joeenv/lib/python3.9/site-packages/ray/tune/trainable/trainable.py", line 349, in train
    result = self.step()
  File "/home/joe/.conda/envs/joeenv/lib/python3.9/site-packages/ray/tune/trainable/function_trainable.py", line 417, in step
    self._report_thread_runner_error(block=True)
  File "/home/joe/.conda/envs/joeenv/lib/python3.9/site-packages/ray/tune/trainable/function_trainable.py", line 589, in _report_thread_runner_error
    raise e
  File "/home/joe/.conda/envs/joeenv/lib/python3.9/site-packages/ray/tune/trainable/function_trainable.py", line 289, in run
    self._entrypoint()
  File "/home/joe/.conda/envs/joeenv/lib/python3.9/site-packages/ray/tune/trainable/function_trainable.py", line 362, in entrypoint
    return self._trainable_func(
  File "/home/joe/.conda/envs/joeenv/lib/python3.9/site-packages/ray/tune/trainable/function_trainable.py", line 684, in _trainable_func
    output = fn()
  File "/home/joe/.conda/envs/joeenv/lib/python3.9/site-packages/ray/tune/trainable/util.py", line 368, in _inner
    inner(config, checkpoint_dir=None)
  File "/home/joe/.conda/envs/joeenv/lib/python3.9/site-packages/ray/tune/trainable/util.py", line 359, in inner
    trainable(config, **fn_kwargs)
  File "/home/joe/fed-tag/cifar_10/classic/adapt/ray_train.py", line 123, in tuning
    args.n_malicious, args.dba,
AttributeError: 'Namespace' object has no attribute 'n_malicious'
